<?xml version="1.0" ?>
<!-- This URDF was automatically created by SolidWorks to URDF Exporter! Originally created by Stephen Brawner (brawner@gmail.com) 
     Commit Version: 1.6.0-4-g7f85cfe  Build Version: 1.6.7995.38578
     For more information, please see http://wiki.ros.org/sw_urdf_exporter -->
<robot
  name="crx_description" xmlns:xacro="http://ros.org/wiki/xacro">
<link name="world"/>
  <link
    name="base_link">
    <inertial>
      <origin
        xyz="-3.06481706674273E-17 -3.99305700828419E-18 0.244422610299825"
        rpy="0 0 0" />
      <mass
        value="40" />
      <inertia
        ixx="31.7856467096501"
        ixy="0.000533354169263688"
        ixz="-0.00809623107461862"
        iyy="31.7878803195643"
        iyz="0.0058154121088785"
        izz="31.7408712499535" />
    </inertial>
    <visual>
      <origin
        xyz="0 0 0"
        rpy="0 0 0" />
      <geometry>
        <mesh
          filename="package://crx_description/meshes/base_link.STL" />
      </geometry>
      <material
        name="">
        <color
          rgba="0.796078431372549 0.823529411764706 0.937254901960784 1" />
      </material>
    </visual>
    <collision>
      <origin
        xyz="0 0 0"
        rpy="0 0 0" />
      <geometry>
        <mesh
          filename="package://crx_description/meshes/base_link.STL" />
      </geometry>
    </collision>
  </link>
<joint name="base_link_joint" type="fixed">
      <origin xyz="0 0 0" rpy="0 0 0"/>
      <parent link="world"/>
      <child link="base_link"/>
  </joint>
  <link
    name="link1">
    <inertial>
      <origin
        xyz="-3.06481706674273E-17 -3.99305700828419E-18 0.244422610299825"
        rpy="0 0 0" />
      <mass
        value="40" />
      <inertia
        ixx="31.7856467096501"
        ixy="0.000533354169263688"
        ixz="-0.00809623107461862"
        iyy="31.7878803195643"
        iyz="0.0058154121088785"
        izz="31.7408712499535" />
    </inertial>
    <visual>
      <origin
        xyz="0 0 0"
        rpy="0 0 0" />
      <geometry>
        <mesh
          filename="package://crx_description/meshes/link1.STL" />
      </geometry>
      <material
        name="">
        <color
          rgba="0.796078431372549 0.823529411764706 0.937254901960784 1" />
      </material>
    </visual>
    <collision>
      <origin
        xyz="0 0 0"
        rpy="0 0 0" />
      <geometry>
        <mesh
          filename="package://crx_description/meshes/link1.STL" />
      </geometry>
    </collision>
  </link>
  <joint
    name="joint1"
    type="revolute">
    <origin
      xyz="0 0 0.086"
      rpy="0 0 0" />
    <parent
      link="base_link" />
    <child
      link="link1" />
    <axis
      xyz="0 0 -1" />
    <limit
     lower="-3.1415"
      upper="3.1415"
      effort="0"
      velocity="0" />
  </joint>
  <link
    name="link2">
    <inertial>
      <origin
        xyz="-3.06481706674273E-17 -3.99305700828419E-18 0.244422610299825"
        rpy="0 0 0" />
      <mass
        value="40" />
      <inertia
        ixx="31.7856467096501"
        ixy="0.000533354169263688"
        ixz="-0.00809623107461862"
        iyy="31.7878803195643"
        iyz="0.0058154121088785"
        izz="31.7408712499535" />
    </inertial>
    <visual>
      <origin
        xyz="0 0 0"
        rpy="0 0 0" />
      <geometry>
        <mesh
          filename="package://crx_description/meshes/link2.STL" />
      </geometry>
      <material
        name="">
        <color
          rgba="1 1 1 1" />
      </material>
    </visual>
    <collision>
      <origin
        xyz="0 0 0"
        rpy="0 0 0" />
      <geometry>
        <mesh
          filename="package://crx_description/meshes/link2.STL" />
      </geometry>
    </collision>
  </link>
  <joint
    name="joint2"
    type="revolute">
    <origin
      xyz="0 0 0.159"
      rpy="1.5707963267949 0 1.5707963267949" />
    <parent
      link="link1" />
    <child
      link="link2" />
    <axis
      xyz="0 0 1" />
    <limit
     lower="-3.1415"
      upper="3.1415"
      effort="0"
      velocity="0" />
  </joint>
  <link
    name="link3">
    <inertial>
      <origin
        xyz="-3.06481706674273E-17 -3.99305700828419E-18 0.244422610299825"
        rpy="0 0 0" />
      <mass
        value="40" />
      <inertia
        ixx="31.7856467096501"
        ixy="0.000533354169263688"
        ixz="-0.00809623107461862"
        iyy="31.7878803195643"
        iyz="0.0058154121088785"
        izz="31.7408712499535" />
    </inertial>
    <visual>
      <origin
        xyz="0 0 0"
        rpy="0 0 0" />
      <geometry>
        <mesh
          filename="package://crx_description/meshes/link3.STL" />
      </geometry>
      <material
        name="">
        <color
          rgba="0.796078431372549 0.823529411764706 0.937254901960784 1" />
      </material>
    </visual>
    <collision>
      <origin
        xyz="0 0 0"
        rpy="0 0 0" />
      <geometry>
        <mesh
          filename="package://crx_description/meshes/link3.STL" />
      </geometry>
    </collision>
  </link>
  <joint
    name="joint3"
    type="revolute">
    <origin
      xyz="0 0.710022037035655 0.076"
      rpy="3.14159265358979 0 1.5707963267949" />
    <parent
      link="link2" />
    <child
      link="link3" />
    <axis
      xyz="0 0 -1" />
    <limit
     lower="-4.7123"
      upper="4.7123"
      effort="0"
      velocity="0" />
  </joint>
  <link
    name="link4">
    <inertial>
      <origin
        xyz="-3.06481706674273E-17 -3.99305700828419E-18 0.244422610299825"
        rpy="0 0 0" />
      <mass
        value="40" />
      <inertia
        ixx="31.7856467096501"
        ixy="0.000533354169263688"
        ixz="-0.00809623107461862"
        iyy="31.7878803195643"
        iyz="0.0058154121088785"
        izz="31.7408712499535" />
    </inertial>
    <visual>
      <origin
        xyz="0 0 0"
        rpy="0 0 0" />
      <geometry>
        <mesh
          filename="package://crx_description/meshes/link4.STL" />
      </geometry>
      <material
        name="">
        <color
          rgba="0.796078431372549 0.823529411764706 0.937254901960784 1" />
      </material>
    </visual>
    <collision>
      <origin
        xyz="0 0 0"
        rpy="0 0 0" />
      <geometry>
        <mesh
          filename="package://crx_description/meshes/link4.STL" />
      </geometry>
    </collision>
  </link>
  <joint
    name="joint4"
    type="revolute">
    <origin
      xyz="-2.20360585476698E-05 0.152996620049638 0.0759999984271975"
      rpy="-1.5707963267949 0 0" />
    <parent
      link="link3" />
    <child
      link="link4" />
    <axis
      xyz="0 0 -1" />
    <limit
     lower="-3.330"
      upper="3.330"
      effort="0"
      velocity="0" />
  </joint>
  <link
    name="link5">
    <inertial>
      <origin
        xyz="-3.06481706674273E-17 -3.99305700828419E-18 0.244422610299825"
        rpy="0 0 0" />
      <mass
        value="40" />
      <inertia
        ixx="31.7856467096501"
        ixy="0.000533354169263688"
        ixz="-0.00809623107461862"
        iyy="31.7878803195643"
        iyz="0.0058154121088785"
        izz="31.7408712499535" />
    </inertial>
    <visual>
      <origin
        xyz="0 0 0"
        rpy="0 0 0" />
      <geometry>
        <mesh
          filename="package://crx_description/meshes/link5.STL" />
      </geometry>
      <material
        name="">
        <color
          rgba="0.796078431372549 0.823529411764706 0.937254901960784 1" />
      </material>
    </visual>
    <collision>
      <origin
        xyz="0 0 0"
        rpy="0 0 0" />
      <geometry>
        <mesh
          filename="package://crx_description/meshes/link5.STL" />
      </geometry>
    </collision>
  </link>
  <joint
    name="joint5"
    type="revolute">
    <origin
      xyz="0 0.0639999984271975 0.387"
      rpy="-1.5707963267949 0 0" />
    <parent
      link="link4" />
    <child
      link="link5" />
    <axis
      xyz="0 0 1" />
    <limit
     lower="-3.1415"
      upper="3.1415"
      effort="0"
      velocity="0" />
  </joint>
  <link
    name="link6">
    <inertial>
      <origin
        xyz="-3.06481706674273E-17 -3.99305700828419E-18 0.244422610299825"
        rpy="0 0 0" />
      <mass
        value="40" />
      <inertia
        ixx="31.7856467096501"
        ixy="0.000533354169263688"
        ixz="-0.00809623107461862"
        iyy="31.7878803195643"
        iyz="0.0058154121088785"
        izz="31.7408712499535" />
    </inertial>
    <visual>
      <origin
        xyz="0 0 0"
        rpy="0 0 0" />
      <geometry>
        <mesh
          filename="package://crx_description/meshes/link6.STL" />
      </geometry>
      <material
        name="">
        <color
          rgba="0.792156862745098 0.819607843137255 0.933333333333333 1" />
      </material>
    </visual>
    <collision>
      <origin
        xyz="0 0 0"
        rpy="0 0 0" />
      <geometry>
        <mesh
          filename="package://crx_description/meshes/link6.STL" />
      </geometry>
    </collision>
  </link>
  <joint
    name="joint6"
    type="revolute">
    <origin
      xyz="0 -0.1525 0.0859999999999998"
      rpy="1.5707963267949 0 0" />
    <parent
      link="link5" />
    <child
      link="link6" />
    <axis
      xyz="0 0 -1" />
    <limit
     lower="-3.926"
      upper="3.926"
      effort="0"
      velocity="0" />
  </joint>
   <ros2_control name="GazeboSystem" type="system">
  <hardware>
    <plugin>gazebo_ros2_control/GazeboSystem</plugin>
  </hardware>
  <joint name="joint1">
    <command_interface name="position">
         <param name="min">-1.5707</param>
         <param name="max">1.5707</param>
     </command_interface>
     <state_interface name="position"/>
     <state_interface name="velocity"/>
  </joint>
     <joint name="joint1">
    <command_interface name="velocity">
         <param name="min">-1000</param>
          <param name="max">1000</param>
     </command_interface>
     <state_interface name="position"/>
     <state_interface name="velocity"/>
  </joint>
  <joint name="joint2">
    <command_interface name="position">
         <param name="min">-1.5707</param>
         <param name="max">1.5707</param>
     </command_interface>
     <state_interface name="position"/>
     <state_interface name="velocity"/>
  </joint>
     <joint name="joint2">
    <command_interface name="velocity">
         <param name="min">-1000</param>
          <param name="max">1000</param>
     </command_interface>
     <state_interface name="position"/>
     <state_interface name="velocity"/>
  </joint>
  <joint name="joint3">
    <command_interface name="position">
         <param name="min">-1.5707</param>
         <param name="max">1.5707</param>
     </command_interface>
     <state_interface name="position"/>
     <state_interface name="velocity"/>
  </joint>
     <joint name="joint3">
    <command_interface name="velocity">
         <param name="min">-1000</param>
          <param name="max">1000</param>
     </command_interface>
     <state_interface name="position"/>
     <state_interface name="velocity"/>
  </joint>
  <joint name="joint4">
    <command_interface name="position">
        <param name="min">-1.5707</param>
         <param name="max">1.5707</param>
    </command_interface>
    <state_interface name="position"/>
    <state_interface name="velocity"/>
  </joint>
     <joint name="joint4">
    <command_interface name="velocity">
         <param name="min">-1000</param>
          <param name="max">1000</param>
     </command_interface>
     <state_interface name="position"/>
     <state_interface name="velocity"/>
  </joint>
  <joint name="joint5">
    <command_interface name="position">
         <param name="min">-1.5707</param>
         <param name="max">1.5707</param>
     </command_interface>
     <state_interface name="position"/>
     <state_interface name="velocity"/>
  </joint>
     <joint name="joint5">
    <command_interface name="velocity">
         <param name="min">-1000</param>
          <param name="max">1000</param>
     </command_interface>
     <state_interface name="position"/>
     <state_interface name="velocity"/>
  </joint>
  <joint name="joint6">
    <command_interface name="position">
         <param name="min">-1.5707</param>
         <param name="max">1.5707</param>
     </command_interface>
     <state_interface name="position"/>
     <state_interface name="velocity"/>
  </joint>
   <joint name="joint6">
    <command_interface name="velocity">
         <param name="min">-1000</param>
          <param name="max">1000</param>
     </command_interface>
     <state_interface name="position"/>
     <state_interface name="velocity"/>
  </joint>
 </ros2_control>
 <gazebo>
    <plugin filename="libgazebo_ros2_control.so" name="gazebo_ros2_control">
        <!-- <robot_param>/robot_description</robot_param>
        <robot_param_node>/robot_state_publisher</robot_param_node>     -->
        <parameters>$(find crx_description)/config/control.yaml</parameters>
    </plugin>
</gazebo>
</robot>